<mujoco model="open_manipulator_x">
  <compiler angle="radian" meshdir="assets" autolimits="true"/>

  <option integrator="implicitfast"/>

  <default>
    <joint armature="0.1" damping="10.0"/>
    <position kp="1000" kv="200" forcerange="-100 100"/>
  </default>

  <asset>
    <mesh name="link1" file="link1.stl" scale="0.001 0.001 0.001"/>
    <mesh name="link2" file="link2.stl" scale="0.001 0.001 0.001"/>
    <mesh name="link3" file="link3.stl" scale="0.001 0.001 0.001"/>
    <mesh name="link4" file="link4.stl" scale="0.001 0.001 0.001"/>
    <mesh name="link5" file="link5.stl" scale="0.001 0.001 0.001"/>
    <mesh name="gripper_left_palm" file="gripper_left_palm.stl" scale="0.001 0.001 0.001"/>
    <mesh name="gripper_right_palm" file="gripper_right_palm.stl" scale="0.001 0.001 0.001"/>
  </asset>

  <worldbody>
    <geom type="mesh" mesh="link1"/>
    <body name="link2" pos="0.012 0 0.017">
      <inertial pos="-0.000301849 0.000540437 0.0474335" quat="0.999915 0.000960074 0.0122201 -0.00449872" mass="0.0984068" diaginertia="3.4553e-05 3.26892e-05 1.88409e-05"/>
      <joint name="joint1" pos="0 0 0" axis="0 0 1" range="-3.14159 3.14159"  />
      <geom pos="0 0 0.019" quat="1 0 0 0" type="mesh" mesh="link2"/>
      <body name="link3" pos="0 0 0.0595">
        <inertial pos="0.0103084 0.000377434 0.101702" quat="0.71133 0.0466763 0.0513691 0.699423" mass="0.138509" diaginertia="0.000342915 0.000335932 5.49578e-05"/>
        <joint name="joint2" pos="0 0 0" axis="0 1 0" range="-1.5 1.5"  />
        <geom type="mesh" mesh="link3"/>
        <body name="link4" pos="0.024 0 0.128">
          <inertial pos="0.0909096 0.000389298 0.000224133" quat="-0.00162881 0.706672 0.0026348 0.707535" mass="0.132746" diaginertia="0.000251551 0.000242311 3.06462e-05"/>
          <joint name="joint3" pos="0 0 0" axis="0 1 0" range="-1.5 1.4"  />
          <geom type="mesh" mesh="link4"/>
          <body name="link5" pos="0.124 0 0">
            <inertial pos="0.0442068 3.684e-07 0.00891422" quat="0.479052 0.479052 -0.520105 0.520105" mass="0.143276" diaginertia="9.3211e-05 8.07871e-05 7.59805e-05"/>
            <joint name="joint4" pos="0 0 0" axis="0 1 0" range="-1.7 1.97"  />
            <geom type="mesh" mesh="link5"/>
            <body name="gripper_left_link" pos="0.0817 0.021 0">
              <inertial pos="0 0 0" mass="0.001" diaginertia="1e-06 1e-06 1e-06"/>
              <joint name="gripper_left_joint" pos="0 0 0" axis="0 1 0" type="slide" range="-0.01 0.019"  />
              <geom type="mesh" mesh="gripper_left_palm"/>
            </body>
            <body name="gripper_right_link" pos="0.0817 -0.021 0">
              <inertial pos="0 0 0" mass="0.001" diaginertia="1e-06 1e-06 1e-06"/>
              <joint name="gripper_right_joint" pos="0 0 0" axis="0 -1 0" type="slide" range="-0.01 0.019"  />
              <geom type="mesh" mesh="gripper_right_palm"/>
            </body>
            <body name="end_effector_target" pos="0.14 0 0">
              <inertial pos="0 0 0" mass="0.001" diaginertia="1e-06 1e-06 1e-06"/>
              <geom type= "box" size="0.005 0.005 0.005" rgba="1 0 0 1" contype="0" conaffinity="0"/>
            </body>
          </body>
        </body>
      </body>
    </body>
  </worldbody>

  <!-- Exclude contact information -->
  <contact>
    <exclude body1="world" body2="link2"/>
  </contact>

  <!-- Define actuators -->
  <actuator>
    <position name="actuator_joint1" joint="joint1" ctrlrange="-3.142 3.142"/>
    <position name="actuator_joint2" joint="joint2" ctrlrange="-1.5 1.5"/>
    <position name="actuator_joint3" joint="joint3" ctrlrange="-1.5 1.4"/>
    <position name="actuator_joint4" joint="joint4" ctrlrange="-1.7 1.97"/>
    <position name="actuator_gripper_joint" joint="gripper_left_joint" ctrlrange="-0.01 0.019"/>
  </actuator>
  <equality>
    <joint name="equality_gripper" active="true" joint1="gripper_left_joint" joint2="gripper_right_joint" polycoef="0 1 0 0 0"/>
  </equality>
</mujoco>
